Workbook

Sheet MultiStartTime
B3: MS-SBLS | C3: MS-SBDF | D3: MS-SBDB | E3: MS-SBDBF | F3: MS-SimT | G3: MS-SimN | H3: MS-SBLSF
A4: 10x3A | B4: 1 | C4: 4.9 | D4: 7.5 | E4: 2.6 | F4: 0.3 | G4: 0.7 | H4: 1
A5: 10x4A | B5: 0.9 | C5: 3.2 | D5: 5.4 | E5: 2.3 | F5: 0.3 | G5: 0.8 | H5: 0.9
A6: 15x3A | B6: 1.3 | C6: 10.1 | D6: 16.1 | E6: 4.3 | F6: 0.3 | G6: 0.8 | H6: 1.3
A7: 15x4A | B7: 1.3 | C7: 11.2 | D7: 18.2 | E7: 4.5 | F7: 0.3 | G7: 0.9 | H7: 1.3
A8: 20x3A | B8: 1.4 | C8: 18.4 | D8: 29.3 | E8: 5.5 | F8: 0.3 | G8: 0.8 | H8: 1.5
A9: 20x4A | B9: 1.6 | C9: 21.8 | D9: 33.8 | E9: 6.3 | F9: 0.4 | G9: 0.9 | H9: 1.6
A10: 25x3A | B10: 1.7 | C10: 25.2 | D10: 43.5 | E10: 7.1 | F10: 0.4 | G10: 1 | H10: 1.7
A11: 25x5A | B11: 2.5 | C11: 66.4 | D11: 114.1 | E11: 13.6 | F11: 0.5 | G11: 1.2 | H11: 2.5
A12: 28x3A | B12: 1.8 | C12: 37.1 | D12: 64.7 | E12: 8 | F12: 0.3 | G12: 0.9 | H12: 1.8
A13: 28x5A | B13: 2.4 | C13: 75.5 | D13: 134.2 | E13: 14 | F13: 0.5 | G13: 1.2 | H13: 2.4
A14: 30x6A | B14: 2.8 | C14: 93.5 | D14: 163.6 | E14: 16.8 | F14: 0.6 | G14: 1.3 | H14: 2.8
A15: 30x8A | B15: 3.1 | C15: 121.8 | D15: 215.4 | E15: 21 | F15: 0.6 | G15: 1.3 | H15: 3.1
... A75: 100x15C | B75: 53.1 | C75: 11129 | D75: 21370.3 | E75: 1274 | F75: 14.3 | G75: 13.1 | H75: 53.4

Sheet CutOff16Dec24
B2: CutOff | F2: NoCutOFF
B3: Best | C3: AvgV | D3: AvgT | F3: Best | G3: AvgV | H3: AvgT
A4: 10x3A | B4: 5441.25 | C4: 5441.25 | D4: 8.76 | F4: 5441.25 | G4: 5441.25 | H4: 8.89 | J4: =IF(B4<F4,1,0) -> 0 | K4: =IF(B4=F4,1,0) -> 1 | L4: =IF(B4>F4,1,0) -> 0 | N4: =IF(C4<G4,1,0) -> 0 | O4: =IF(C4=G4,1,0) -> 1 | P4: =IF(C4>G4,1,0) -> 0
A5: 10x4A | B5: 7533.59 | C5: 7533.59 | D5: 2.09 | F5: 7502.69 | G5: 7502.69 | H5: 347.61 | J5: =IF(B5<F5,1,0) -> 0 | K5: =IF(B5=F5,1,0) -> 0 | L5: =IF(B5>F5,1,0) -> 1 | N5: =IF(C5<G5,1,0) -> 0 | O5: =IF(C5=G5,1,0) -> 0 | P5: =IF(C5>G5,1,0) -> 1
A6: 15x3A | B6: 10019 | C6: 10019 | D6: 14.54 | F6: 10019 | G6: 10019 | H6: 28.93 | J6: =IF(B6<F6,1,0) -> 0 | K6: =IF(B6=F6,1,0) -> 1 | L6: =IF(B6>F6,1,0) -> 0 | N6: =IF(C6<G6,1,0) -> 0 | O6: =IF(C6=G6,1,0) -> 1 | P6: =IF(C6>G6,1,0) -> 0
A7: 15x4A | B7: 13226.2 | C7: 13226.2 | D7: 42.53 | F7: 13226.2 | G7: 13226.2 | H7: 38.72 | J7: =IF(B7<F7,1,0) -> 0 | K7: =IF(B7=F7,1,0) -> 1 | L7: =IF(B7>F7,1,0) -> 0 | N7: =IF(C7<G7,1,0) -> 0 | O7: =IF(C7=G7,1,0) -> 1 | P7: =IF(C7>G7,1,0) -> 0
A8: 20x3A | B8: 17695 | C8: 17695 | D8: 128.78 | F8: 17695 | G8: 17695 | H8: 99.4 | J8: =IF(B8<F8,1,0) -> 0 | K8: =IF(B8=F8,1,0) -> 1 | L8: =IF(B8>F8,1,0) -> 0 | N8: =IF(C8<G8,1,0) -> 0 | O8: =IF(C8=G8,1,0) -> 1 | P8: =IF(C8>G8,1,0) -> 0
A9: 20x4A | B9: 17805.75 | C9: 17805.75 | D9: 176.61 | F9: 17805.75 | G9: 17805.75 | H9: 371.38 | J9: =IF(B9<F9,1,0) -> 0 | K9: =IF(B9=F9,1,0) -> 1 | L9: =IF(B9>F9,1,0) -> 0 | N9: =IF(C9<G9,1,0) -> 0 | O9: =IF(C9=G9,1,0) -> 1 | P9: =IF(C9>G9,1,0) -> 0
A10: 25x3A | B10: 70463.51 | C10: 70464.31 | D10: 968.3 | F10: 70463.2 | G10: 70464.89 | H10: 608.46 | J10: =IF(B10<F10,1,0) -> 0 | K10: =IF(B10=F10,1,0) -> 0 | L10: =IF(B10>F10,1,0) -> 1 | N10: =IF(C10<G10,1,0) -> 1 | O10: =IF(C10=G10,1,0) -> 0 | P10: =IF(C10>G10,1,0) -> 0
A11: 25x5A | B11: 35221.33 | C11: 35222.38 | D11: 1192.27 | F11: 35221.33 | G11: 35222.59 | H11: 1239.97 | J11: =IF(B11<F11,1,0) -> 0 | K11: =IF(B11=F11,1,0) -> 1 | L11: =IF(B11>F11,1,0) -> 0 | N11: =IF(C11<G11,1,0) -> 1 | O11: =IF(C11=G11,1,0) -> 0 | P11: =IF(C11>G11,1,0) -> 0
A12: 28x3A | B12: 65003.48 | C12: 65003.48 | D12: 304.02 | F12: 65003.48 | G12: 65003.54 | H12: 852.85 | J12: =IF(B12<F12,1,0) -> 0 | K12: =IF(B12=F12,1,0) -> 1 | L12: =IF(B12>F12,1,0) -> 0 | N12: =IF(C12<G12,1,0) -> 1 | O12: =IF(C12=G12,1,0) -> 0 | P12: =IF(C12>G12,1,0) -> 0
A13: 28x5A | B13: 63293.84 | C13: 63297.9 | D13: 829.87 | F13: 63293.84 | G13: 63299.86 | H13: 1167.97 | J13: =IF(B13<F13,1,0) -> 0 | K13: =IF(B13=F13,1,0) -> 1 | L13: =IF(B13>F13,1,0) -> 0 | N13: =IF(C13<G13,1,0) -> 1 | O13: =IF(C13=G13,1,0) -> 0 | P13: =IF(C13>G13,1,0) -> 0
A14: 30x6A | B14: 53201.45 | C14: 53207.38 | D14: 1145.47 | F14: 53205.04 | G14: 53209.78 | H14: 1320.19 | J14: =IF(B14<F14,1,0) -> 1 | K14: =IF(B14=F14,1,0) -> 0 | L14: =IF(B14>F14,1,0) -> 0 | N14: =IF(C14<G14,1,0) -> 1 | O14: =IF(C14=G14,1,0) -> 0 | P14: =IF(C14>G14,1,0) -> 0
A15: 30x8A | B15: 61352.43 | C15: 61359.5 | D15: 1062.79 | F15: 61353.87 | G15: 61369.19 | H15: 1393.86 | J15: =IF(B15<F15,1,0) -> 1 | K15: =IF(B15=F15,1,0) -> 0 | L15: =IF(B15>F15,1,0) -> 0 | N15: =IF(C15<G15,1,0) -> 1 | O15: =IF(C15=G15,1,0) -> 0 | P15: =IF(C15>G15,1,0) -> 0
... A75: 100x15A | B75: 2239781.4 | C75: 2244887 | D75: 868.4 | F75: 2239738.4 | G75: 2250275.7 | H75: 1010.4 | J75: =IF(B75<F75,1,0) -> 0 | K75: =IF(B75=F75,1,0) -> 0 | L75: =IF(B75>F75,1,0) -> 1 | N75: =IF(C75<G75,1,0) -> 1 | O75: =IF(C75=G75,1,0) -> 0 | P75: =IF(C75>G75,1,0) -> 0
J76: =SUM(J4:J75) -> 47 | K76: =SUM(K4:K75) -> 13 | L76: =SUM(L4:L75) -> 12 | N76: =SUM(N4:N75) -> 58 | O76: =SUM(O4:O75) -> 7 | P76: =SUM(P4:P75) -> 7
I77: A | J77: =SUM(J4:J27) -> 13 | K77: =SUM(K4:K27) -> 8 | L77: =SUM(L4:L27) -> 3 | N77: =SUM(N4:N27) -> 18 | O77: =SUM(O4:O27) -> 5 | P77: =SUM(P4:P27) -> 1
I78: B | J78: =SUM(J28:J51) -> 20 | K78: =SUM(K28:K51) -> 3 | L78: =SUM(L28:L51) -> 1 | N78: =SUM(N28:N51) -> 19 | O78: =SUM(O28:O51) -> 2 | P78: =SUM(P28:P51) -> 3
I79: C | J79: =SUM(J52:J75) -> 14 | K79: =SUM(K52:K75) -> 2 | L79: =SUM(L52:L75) -> 8 | N79: =SUM(N52:N75) -> 21 | O79: =SUM(O52:O75) -> 0 | P79: =SUM(P52:P75) -> 3
I80: CutOff vs NoCutOff | J80: #Wins | K80: #Ties | L80: #Losses
I81: BestObj | J81: =J76 -> 47 | K81: =K76 -> 13 | L81: =L76 -> 12
I82: AvgObj | J82: =N76 -> 58 | K82: =O76 -> 7 | L82: =P76 -> 7
M85: CutOff vs NoCutOff
M86: Best | T86: AvgObj
M87: #Wins | O87: #Ties | Q87: #losses | S87: p-value | T87: & | U87: #Wins | W87: #Ties | Y87: #losses | AA87: p-value
K88: SetA | L88: & | M88: =J77 -> 13 | N88: & | O88: =K77 -> 8 | P88: & | Q88: =L77 -> 3 | R88: & | S88: 1.192e-07 | T88: & | U88: =N77 -> 18 | V88: & | W88: =O77 -> 5 | X88: & | Y88: =P77 -> 1 | Z88: & | AA88: 1.192e-07 | AB88: \\
K89: SetB | L89: & | M89: =J78 -> 20 | N89: & | O89: =K78 -> 3 | P89: & | Q89: =L78 -> 1 | R89: & | S89: 1.192e-07 | T89: & | U89: =N78 -> 19 | V89: & | W89: =O78 -> 2 | X89: & | Y89: =P78 -> 3 | Z89: & | AA89: 1.192e-07 | AB89: \\
K90: SetC | L90: & | M90: =J79 -> 14 | N90: & | O90: =K79 -> 2 | P90: & | Q90: =L79 -> 8 | R90: & | S90: 8.345e-07 | T90: & | U90: =N79 -> 21 | V90: & | W90: =O79 -> 0 | X90: & | Y90: =P79 -> 3 | Z90: & | AA90: 2.98e-06 | AB90: \\
K91: Total | L91: & | M91: =J76 -> 47 | N91: & | O91: =K76 -> 13 | P91: & | Q91: =L76 -> 12 | R91: & | S91: 6.329e-05 | T91: & | U91: =N76 -> 58 | V91: & | W91: =O76 -> 7 | X91: & | Y91: =P76 -> 7 | Z91: & | AA91: 1.192e-07 | AB91: \\
K92: p-value | L92: & | S92: &&& | AB92: \\
M96: CutOff vs NoCutOff
M97: Best | R97: AvgObj
M98: #Wins | O98: #Ties | Q98: #losses | R98: & | S98: #Wins | U98: #Ties | W98: #losses
K99: SetA | L99: & | M99: =J77 -> 13 | N99: & | O99: =K77 -> 8 | P99: & | Q99: =L77 -> 3 | R99: & | S99: =N77 -> 18 | T99: & | U99: =O77 -> 5 | V99: & | W99: =P77 -> 1 | X99: & | Y99: \\
K100: SetB | L100: & | M100: =J78 -> 20 | N100: & | O100: =K78 -> 3 | P100: & | Q100: =L78 -> 1 | R100: & | S100: =N78 -> 19 | T100: & | U100: =O78 -> 2 | V100: & | W100: =P78 -> 3 | X100: & | Y100: \\
K101: SetC | L101: & | M101: =J79 -> 14 | N101: & | O101: =K79 -> 2 | P101: & | Q101: =L79 -> 8 | R101: & | S101: =N79 -> 21 | T101: & | U101: =O79 -> 0 | V101: & | W101: =P79 -> 3 | X101: & | Y101: \\
K102: Total | L102: & | M102: =J81 -> 47 | N102: & | O102: =K81 -> 13 | P102: & | Q102: =L81 -> 12 | R102: & | S102: =J82 -> 58 | T102: & | U102: =K82 -> 7 | V102: & | W102: =L82 -> 7 | X102: & | Y102: \\
K103: p-value | L103: & | M103: 2.02e-06 | R103: &&& | U103: 5.141e-10 | Y103: \\

Sheet FastEvaluation
C1: SimHGS | H1: NOFAST
A2: min best | C2: Best | D2: AvgV | E2: AvgT | F2: E | H2: Best | I2: Avg | J2: AvgT | K2: E | L2: min Avg | M2: minE
A3: =MIN(C3,H3) -> 5441.25 | B3: 10x3A | C3: 5441.25 | D3: 5441.25 | E3: 8.76 | F3: 5443.3 | H3: 5443.25 | I3: 5451.98 | J3: 54.7 | K3: 5445.34 | L3: =MIN(D3,I3) -> 5441.25 | M3: =MIN(F3,K3) -> 5443.3 | N3: =IF(C3>$A3,0,1) -> 1 | O3: =IF(H3>$A3,0,1) -> 0 | P3: =IF(D3>$L3,0,1) -> 1 | Q3: =IF(I3>$L3,0,1) -> 0 | R3: =IF(F3>$M3,0,1) -> 1 | S3: =IF(K3>$M3,0,1) -> 0 | V3: =IF(N3=O3,1,0) -> 0 | Y3: =IF(P3=Q3,1,0) -> 0
A4: =MIN(C4,H4) -> 7533.59 | B4: 10x4A | C4: 7533.59 | D4: 7533.59 | E4: 2.09 | F4: 7528.4 | H4: 7533.59 | I4: 7533.63 | J4: 10 | K4: 7528.43 | L4: =MIN(D4,I4) -> 7533.59 | M4: =MIN(F4,K4) -> 7528.4 | N4: =IF(C4>$A4,0,1) -> 1 | O4: =IF(H4>$A4,0,1) -> 1 | P4: =IF(D4>$L4,0,1) -> 1 | Q4: =IF(I4>$L4,0,1) -> 0 | R4: =IF(F4>$M4,0,1) -> 1 | S4: =IF(K4>$M4,0,1) -> 0 | V4: =IF(N4=O4,1,0) -> 1 | Y4: =IF(P4=Q4,1,0) -> 0
A5: =MIN(C5,H5) -> 10019 | B5: 15x3A | C5: 10019 | D5: 10019 | E5: 14.54 | F5: 10019 | H5: 10023.13 | I5: 10024.28 | J5: 9.67 | K5: 10020.87 | L5: =MIN(D5,I5) -> 10019 | M5: =MIN(F5,K5) -> 10019 | N5: =IF(C5>$A5,0,1) -> 1 | O5: =IF(H5>$A5,0,1) -> 0 | P5: =IF(D5>$L5,0,1) -> 1 | Q5: =IF(I5>$L5,0,1) -> 0 | R5: =IF(F5>$M5,0,1) -> 1 | S5: =IF(K5>$M5,0,1) -> 0 | V5: =IF(N5=O5,1,0) -> 0 | Y5: =IF(P5=Q5,1,0) -> 0
A6: =MIN(C6,H6) -> 13226.2 | B6: 15x4A | C6: 13226.2 | D6: 13226.2 | E6: 42.53 | F6: 13227.1 | H6: 13235.29 | I6: 13238 | J6: 113.81 | K6: 13237.4 | L6: =MIN(D6,I6) -> 13226.2 | M6: =MIN(F6,K6) -> 13227.1 | N6: =IF(C6>$A6,0,1) -> 1 | O6: =IF(H6>$A6,0,1) -> 0 | P6: =IF(D6>$L6,0,1) -> 1 | Q6: =IF(I6>$L6,0,1) -> 0 | R6: =IF(F6>$M6,0,1) -> 1 | S6: =IF(K6>$M6,0,1) -> 0 | V6: =IF(N6=O6,1,0) -> 0 | Y6: =IF(P6=Q6,1,0) -> 0
A7: =MIN(C7,H7) -> 17695 | B7: 20x3A | C7: 17695 | D7: 17695 | E7: 128.78 | F7: 17695 | H7: 17695 | I7: 17695 | J7: 264.83 | K7: 17695 | L7: =MIN(D7,I7) -> 17695 | M7: =MIN(F7,K7) -> 17695 | N7: =IF(C7>$A7,0,1) -> 1 | O7: =IF(H7>$A7,0,1) -> 1 | P7: =IF(D7>$L7,0,1) -> 1 | Q7: =IF(I7>$L7,0,1) -> 1 | R7: =IF(F7>$M7,0,1) -> 1 | S7: =IF(K7>$M7,0,1) -> 1 | V7: =IF(N7=O7,1,0) -> 1 | Y7: =IF(P7=Q7,1,0) -> 1
A8: =MIN(C8,H8) -> 17805.75 | B8: 20x4A | C8: 17805.75 | D8: 17805.75 | E8: 176.61 | F8: 17794.8 | H8: 17805.75 | I8: 17806.1 | J8: 463.36 | K8: 17794.76 | L8: =MIN(D8,I8) -> 17805.75 | M8: =MIN(F8,K8) -> 17794.76 | N8: =IF(C8>$A8,0,1) -> 1 | O8: =IF(H8>$A8,0,1) -> 1 | P8: =IF(D8>$L8,0,1) -> 1 | Q8: =IF(I8>$L8,0,1) -> 0 | R8: =IF(F8>$M8,0,1) -> 0 | S8: =IF(K8>$M8,0,1) -> 1 | V8: =IF(N8=O8,1,0) -> 1 | Y8: =IF(P8=Q8,1,0) -> 0
A9: =MIN(C9,H9) -> 70463.51 | B9: 25x3A | C9: 70463.51 | D9: 70464.31 | E9: 968.3 | F9: 70465.9 | H9: 70469.78 | I9: 70472.22 | J9: 673.77 | K9: 70471.27 | L9: =MIN(D9,I9) -> 70464.31 | M9: =MIN(F9,K9) -> 70465.9 | N9: =IF(C9>$A9,0,1) -> 1 | O9: =IF(H9>$A9,0,1) -> 0 | P9: =IF(D9>$L9,0,1) -> 1 | Q9: =IF(I9>$L9,0,1) -> 0 | R9: =IF(F9>$M9,0,1) -> 1 | S9: =IF(K9>$M9,0,1) -> 0 | V9: =IF(N9=O9,1,0) -> 0 | Y9: =IF(P9=Q9,1,0) -> 0
A10: =MIN(C10,H10) -> 35221.33 | B10: 25x5A | C10: 35221.33 | D10: 35222.38 | E10: 1192.27 | F10: 35227.2 | H10: 35225.63 | I10: 35232.44 | J10: 1276.21 | K10: 35234.07 | L10: =MIN(D10,I10) -> 35222.38 | M10: =MIN(F10,K10) -> 35227.2 | N10: =IF(C10>$A10,0,1) -> 1 | O10: =IF(H10>$A10,0,1) -> 0 | P10: =IF(D10>$L10,0,1) -> 1 | Q10: =IF(I10>$L10,0,1) -> 0 | R10: =IF(F10>$M10,0,1) -> 1 | S10: =IF(K10>$M10,0,1) -> 0 | V10: =IF(N10=O10,1,0) -> 0 | Y10: =IF(P10=Q10,1,0) -> 0
A11: =MIN(C11,H11) -> 65003.48 | B11: 28x3A | C11: 65003.48 | D11: 65003.48 | E11: 304.02 | F11: 65050.5 | H11: 65004.01 | I11: 65004.57 | J11: 862.57 | K11: 65011.39 | L11: =MIN(D11,I11) -> 65003.48 | M11: =MIN(F11,K11) -> 65011.39 | N11: =IF(C11>$A11,0,1) -> 1 | O11: =IF(H11>$A11,0,1) -> 0 | P11: =IF(D11>$L11,0,1) -> 1 | Q11: =IF(I11>$L11,0,1) -> 0 | R11: =IF(F11>$M11,0,1) -> 0 | S11: =IF(K11>$M11,0,1) -> 1 | V11: =IF(N11=O11,1,0) -> 0 | Y11: =IF(P11=Q11,1,0) -> 0
A12: =MIN(C12,H12) -> 63293.84 | B12: 28x5A | C12: 63293.84 | D12: 63297.9 | E12: 829.87 | F12: 63297 | H12: 63299.55 | I12: 63330.94 | J12: 1247.78 | K12: 63303.64 | L12: =MIN(D12,I12) -> 63297.9 | M12: =MIN(F12,K12) -> 63297 | N12: =IF(C12>$A12,0,1) -> 1 | O12: =IF(H12>$A12,0,1) -> 0 | P12: =IF(D12>$L12,0,1) -> 1 | Q12: =IF(I12>$L12,0,1) -> 0 | R12: =IF(F12>$M12,0,1) -> 1 | S12: =IF(K12>$M12,0,1) -> 0 | V12: =IF(N12=O12,1,0) -> 0 | Y12: =IF(P12=Q12,1,0) -> 0
A13: =MIN(C13,H13) -> 53201.45 | B13: 30x6A | C13: 53201.45 | D13: 53207.38 | E13: 1145.47 | F13: 53200.2 | H13: 53230.09 | I13: 53246.59 | J13: 1573.86 | K13: 53236.26 | L13: =MIN(D13,I13) -> 53207.38 | M13: =MIN(F13,K13) -> 53200.2 | N13: =IF(C13>$A13,0,1) -> 1 | O13: =IF(H13>$A13,0,1) -> 0 | P13: =IF(D13>$L13,0,1) -> 1 | Q13: =IF(I13>$L13,0,1) -> 0 | R13: =IF(F13>$M13,0,1) -> 1 | S13: =IF(K13>$M13,0,1) -> 0 | V13: =IF(N13=O13,1,0) -> 0 | Y13: =IF(P13=Q13,1,0) -> 0
A14: =MIN(C14,H14) -> 61352.43 | B14: 30x8A | C14: 61352.43 | D14: 61359.5 | E14: 1062.79 | F14: 61362.3 | H14: 61402.29 | I14: 61661.85 | J14: 1613.7 | K14: 61423.51 | L14: =MIN(D14,I14) -> 61359.5 | M14: =MIN(F14,K14) -> 61362.3 | N14: =IF(C14>$A14,0,1) -> 1 | O14: =IF(H14>$A14,0,1) -> 0 | P14: =IF(D14>$L14,0,1) -> 1 | Q14: =IF(I14>$L14,0,1) -> 0 | R14: =IF(F14>$M14,0,1) -> 1 | S14: =IF(K14>$M14,0,1) -> 0 | V14: =IF(N14=O14,1,0) -> 0 | Y14: =IF(P14=Q14,1,0) -> 0
... A26: =MIN(C26,H26) -> 749159.93 | B26: 100x15A | C26: 749159.93 | D26: 751312.57 | E26: 1347.21 | F26: 749120 | H26: 771094.61 | I26: 778248.79 | J26: 1846.04 | K26: 771132.21 | L26: =MIN(D26,I26) -> 751312.57 | M26: =MIN(F26,K26) -> 749120 | N26: =IF(C26>$A26,0,1) -> 1 | O26: =IF(H26>$A26,0,1) -> 0 | P26: =IF(D26>$L26,0,1) -> 1 | Q26: =IF(I26>$L26,0,1) -> 0 | R26: =IF(F26>$M26,0,1) -> 1 | S26: =IF(K26>$M26,0,1) -> 0 | V26: =IF(N26=O26,1,0) -> 0 | Y26: =IF(P26=Q26,1,0) -> 0
T27: =SUM(N3:N26) -> 24 | U27: =SUM(O3:O26) -> 3 | V27: =SUM(V3:V26) -> 3 | W27: =SUM(P3:P26) -> 24 | X27: =SUM(Q3:Q26) -> 1 | Y27: =SUM(Y3:Y26) -> 1
A28: =MIN(C28,H28) -> 17588.01 | B28: 10x3B | C28: 17588.01 | D28: 17588.01 | E28: 24.11 | F28: 17568.7 | H28: 17588.52 | I28: 17588.52 | J28: 65.81 | K28: 17567.92 | L28: =MIN(D28,I28) -> 17588.01 | M28: =MIN(F28,K28) -> 17567.92 | N28: =IF(C28>$A28,0,1) -> 1 | O28: =IF(H28>$A28,0,1) -> 0 | P28: =IF(D28>$L28,0,1) -> 1 | Q28: =IF(I28>$L28,0,1) -> 0 | R28: =IF(F28>$M28,0,1) -> 0 | S28: =IF(K28>$M28,0,1) -> 1 | V28: =IF(N28=O28,1,0) -> 0 | Y28: =IF(P28=Q28,1,0) -> 0
A29: =MIN(C29,H29) -> 24588.2 | B29: 10x4B | C29: 24588.2 | D29: 24588.2 | E29: 5.91 | F29: 24549.1 | H29: 24592.14 | I29: 24592.69 | J29: 44.46 | K29: 24554.84 | L29: =MIN(D29,I29) -> 24588.2 | M29: =MIN(F29,K29) -> 24549.1 | N29: =IF(C29>$A29,0,1) -> 1 | O29: =IF(H29>$A29,0,1) -> 0 | P29: =IF(D29>$L29,0,1) -> 1 | Q29: =IF(I29>$L29,0,1) -> 0 | R29: =IF(F29>$M29,0,1) -> 1 | S29: =IF(K29>$M29,0,1) -> 0 | V29: =IF(N29=O29,1,0) -> 0 | Y29: =IF(P29=Q29,1,0) -> 0
A30: =MIN(C30,H30) -> 37798.25 | B30: 15x3B | C30: 37798.25 | D30: 37798.93 | E30: 934.95 | F30: 37788.2 | H30: 37799.63 | I30: 37812.68 | J30: 1010.18 | K30: 37788.91 | L30: =MIN(D30,I30) -> 37798.93 | M30: =MIN(F30,K30) -> 37788.2 | N30: =IF(C30>$A30,0,1) -> 1 | O30: =IF(H30>$A30,0,1) -> 0 | P30: =IF(D30>$L30,0,1) -> 1 | Q30: =IF(I30>$L30,0,1) -> 0 | R30: =IF(F30>$M30,0,1) -> 1 | S30: =IF(K30>$M30,0,1) -> 0 | V30: =IF(N30=O30,1,0) -> 0 | Y30: =IF(P30=Q30,1,0) -> 0
A31: =MIN(C31,H31) -> 50542.02 | B31: 15x4B | C31: 50542.02 | D31: 50549.05 | E31: 1161.59 | F31: 50566.1 | H31: 50561.07 | I31: 50600.47 | J31: 1116.87 | K31: 50586.4 | L31: =MIN(D31,I31) -> 50549.05 | M31: =MIN(F31,K31) -> 50566.1 | N31: =IF(C31>$A31,0,1) -> 1 | O31: =IF(H31>$A31,0,1) -> 0 | P31: =IF(D31>$L31,0,1) -> 1 | Q31: =IF(I31>$L31,0,1) -> 0 | R31: =IF(F31>$M31,0,1) -> 1 | S31: =IF(K31>$M31,0,1) -> 0 | V31: =IF(N31=O31,1,0) -> 0 | Y31: =IF(P31=Q31,1,0) -> 0
A32: =MIN(C32,H32) -> 62467.74 | B32: 20x3B | C32: 62467.74 | D32: 62470.96 | E32: 1096.65 | F32: 62481.1 | H32: 62500.72 | I32: 62586.42 | J32: 1192.3 | K32: 62502.84 | L32: =MIN(D32,I32) -> 62470.96 | M32: =MIN(F32,K32) -> 62481.1 | N32: =IF(C32>$A32,0,1) -> 1 | O32: =IF(H32>$A32,0,1) -> 0 | P32: =IF(D32>$L32,0,1) -> 1 | Q32: =IF(I32>$L32,0,1) -> 0 | R32: =IF(F32>$M32,0,1) -> 1 | S32: =IF(K32>$M32,0,1) -> 0 | V32: =IF(N32=O32,1,0) -> 0 | Y32: =IF(P32=Q32,1,0) -> 0
A33: =MIN(C33,H33) -> 67575.55 | B33: 20x4B | C33: 67575.55 | D33: 67688.62 | E33: 919.69 | F33: 67545.8 | H33: 67665.92 | I33: 67784.22 | J33: 1397.02 | K33: 67626.12 | L33: =MIN(D33,I33) -> 67688.62 | M33: =MIN(F33,K33) -> 67545.8 | N33: =IF(C33>$A33,0,1) -> 1 | O33: =IF(H33>$A33,0,1) -> 0 | P33: =IF(D33>$L33,0,1) -> 1 | Q33: =IF(I33>$L33,0,1) -> 0 | R33: =IF(F33>$M33,0,1) -> 1 | S33: =IF(K33>$M33,0,1) -> 0 | V33: =IF(N33=O33,1,0) -> 0 | Y33: =IF(P33=Q33,1,0) -> 0
A34: =MIN(C34,H34) -> 241551.04 | B34: 25x3B | C34: 241551.04 | D34: 241605.58 | E34: 1094.73 | F34: 241567.5 | H34: 241578.79 | I34: 241675.37 | J34: 1368.18 | K34: 241592.11 | L34: =MIN(D34,I34) -> 241605.58 | M34: =MIN(F34,K34) -> 241567.5 | N34: =IF(C34>$A34,0,1) -> 1 | O34: =IF(H34>$A34,0,1) -> 0 | P34: =IF(D34>$L34,0,1) -> 1 | Q34: =IF(I34>$L34,0,1) -> 0 | R34: =IF(F34>$M34,0,1) -> 1 | S34: =IF(K34>$M34,0,1) -> 0 | V34: =IF(N34=O34,1,0) -> 0 | Y34: =IF(P34=Q34,1,0) -> 0
A35: =MIN(C35,H35) -> 114511.99 | B35: 25x5B | C35: 114511.99 | D35: 114671.09 | E35: 1505.15 | F35: 114496.9 | H35: 114846.46 | I35: 115265.27 | J35: 1586.09 | K35: 114829.9 | L35: =MIN(D35,I35) -> 114671.09 | M35: =MIN(F35,K35) -> 114496.9 | N35: =IF(C35>$A35,0,1) -> 1 | O35: =IF(H35>$A35,0,1) -> 0 | P35: =IF(D35>$L35,0,1) -> 1 | Q35: =IF(I35>$L35,0,1) -> 0 | R35: =IF(F35>$M35,0,1) -> 1 | S35: =IF(K35>$M35,0,1) -> 0 | V35: =IF(N35=O35,1,0) -> 0 | Y35: =IF(P35=Q35,1,0) -> 0
A36: =MIN(C36,H36) -> 241918.34 | B36: 28x3B | C36: 241918.34 | D36: 241992.26 | E36: 1234.61 | F36: 241922.1 | H36: 242076.19 | I36: 242178.01 | J36: 1519.91 | K36: 242079.76 | L36: =MIN(D36,I36) -> 241992.26 | M36: =MIN(F36,K36) -> 241922.1 | N36: =IF(C36>$A36,0,1) -> 1 | O36: =IF(H36>$A36,0,1) -> 0 | P36: =IF(D36>$L36,0,1) -> 1 | Q36: =IF(I36>$L36,0,1) -> 0 | R36: =IF(F36>$M36,0,1) -> 1 | S36: =IF(K36>$M36,0,1) -> 0 | V36: =IF(N36=O36,1,0) -> 0 | Y36: =IF(P36=Q36,1,0) -> 0
A37: =MIN(C37,H37) -> 195827.52 | B37: 28x5B | C37: 195827.52 | D37: 196148.55 | E37: 1159.56 | F37: 195835.5 | H37: 196378.8 | I37: 196552.48 | J37: 1433.74 | K37: 196401.89 | L37: =MIN(D37,I37) -> 196148.55 | M37: =MIN(F37,K37) -> 195835.5 | N37: =IF(C37>$A37,0,1) -> 1 | O37: =IF(H37>$A37,0,1) -> 0 | P37: =IF(D37>$L37,0,1) -> 1 | Q37: =IF(I37>$L37,0,1) -> 0 | R37: =IF(F37>$M37,0,1) -> 1 | S37: =IF(K37>$M37,0,1) -> 0 | V37: =IF(N37=O37,1,0) -> 0 | Y37: =IF(P37=Q37,1,0) -> 0
A38: =MIN(C38,H38) -> 194666.04 | B38: 30x6B | C38: 194666.04 | D38: 194897.27 | E38: 1560.59 | F38: 194757.9 | H38: 195332.26 | I38: 195756.72 | J38: 1416.04 | K38: 195457 | L38: =MIN(D38,I38) -> 194897.27 | M38: =MIN(F38,K38) -> 194757.9 | N38: =IF(C38>$A38,0,1) -> 1 | O38: =IF(H38>$A38,0,1) -> 0 | P38: =IF(D38>$L38,0,1) -> 1 | Q38: =IF(I38>$L38,0,1) -> 0 | R38: =IF(F38>$M38,0,1) -> 1 | S38: =IF(K38>$M38,0,1) -> 0 | V38: =IF(N38=O38,1,0) -> 0 | Y38: =IF(P38=Q38,1,0) -> 0
A39: =MIN(C39,H39) -> 201236.17 | B39: 30x8B | C39: 201236.17 | D39: 201479.97 | E39: 1418.54 | F39: 201248.1 | H39: 201606.79 | I39: 202346.24 | J39: 1460.73 | K39: 201606.98 | L39: =MIN(D39,I39) -> 201479.97 | M39: =MIN(F39,K39) -> 201248.1 | N39: =IF(C39>$A39,0,1) -> 1 | O39: =IF(H39>$A39,0,1) -> 0 | P39: =IF(D39>$L39,0,1) -> 1 | Q39: =IF(I39>$L39,0,1) -> 0 | R39: =IF(F39>$M39,0,1) -> 1 | S39: =IF(K39>$M39,0,1) -> 0 | V39: =IF(N39=O39,1,0) -> 0 | Y39: =IF(P39=Q39,1,0) -> 0
... A51: =MIN(C51,H51) -> 2525547.2 | B51: 100x15B | C51: 2525547.2 | D51: 2531717.2 | E51: 1294.62 | F51: 2525141.9 | H51: 2652854.5 | I51: 2676599.4 | J51: 2084.48 | K51: 2652508.7 | L51: =MIN(D51,I51) -> 2531717.2 | M51: =MIN(F51,K51) -> 2525141.9 | N51: =IF(C51>$A51,0,1) -> 1 | O51: =IF(H51>$A51,0,1) -> 0 | P51: =IF(D51>$L51,0,1) -> 1 | Q51: =IF(I51>$L51,0,1) -> 0 | R51: =IF(F51>$M51,0,1) -> 1 | S51: =IF(K51>$M51,0,1) -> 0 | V51: =IF(N51=O51,1,0) -> 0 | Y51: =IF(P51=Q51,1,0) -> 0
T52: =SUM(N28:N51) -> 24 | U52: =SUM(O28:O51) -> 0 | V52: =SUM(V28:V51) -> 0 | W52: =SUM(P28:P51) -> 24 | X52: =SUM(Q28:Q51) -> 0 | Y52: =SUM(Y28:Y51) -> 0
A53: =MIN(C53,H53) -> 43.81 | B53: 10x3C | C53: 43.81 | D53: 47.11 | E53: 960.01 | F53: 51.2 | H53: 44.68 | I53: 52.27 | J53: 817.3 | K53: 46.02 | L53: =MIN(D53,I53) -> 47.11 | M53: =MIN(F53,K53) -> 46.02 | N53: =IF(C53>$A53,0,1) -> 1 | O53: =IF(H53>$A53,0,1) -> 0 | P53: =IF(D53>$L53,0,1) -> 1 | Q53: =IF(I53>$L53,0,1) -> 0 | R53: =IF(F53>$M53,0,1) -> 0 | S53: =IF(K53>$M53,0,1) -> 1 | V53: =IF(N53=O53,1,0) -> 0 | Y53: =IF(P53=Q53,1,0) -> 0
A54: =MIN(C54,H54) -> 17 | B54: 10x4C | C54: 17 | D54: 19.7 | E54: 1023 | F54: 23.2 | H54: 17 | I54: 27.32 | J54: 836.62 | K54: 23.18 | L54: =MIN(D54,I54) -> 19.7 | M54: =MIN(F54,K54) -> 23.18 | N54: =IF(C54>$A54,0,1) -> 1 | O54: =IF(H54>$A54,0,1) -> 1 | P54: =IF(D54>$L54,0,1) -> 1 | Q54: =IF(I54>$L54,0,1) -> 0 | R54: =IF(F54>$M54,0,1) -> 0 | S54: =IF(K54>$M54,0,1) -> 1 | V54: =IF(N54=O54,1,0) -> 1 | Y54: =IF(P54=Q54,1,0) -> 0
A55: =MIN(C55,H55) -> 8264.02 | B55: 15x3C | C55: 8264.02 | D55: 8342.88 | E55: 297.22 | F55: 8288.9 | H55: 8328.75 | I55: 8480.82 | J55: 414.45 | K55: 8284.32 | L55: =MIN(D55,I55) -> 8342.88 | M55: =MIN(F55,K55) -> 8284.32 | N55: =IF(C55>$A55,0,1) -> 1 | O55: =IF(H55>$A55,0,1) -> 0 | P55: =IF(D55>$L55,0,1) -> 1 | Q55: =IF(I55>$L55,0,1) -> 0 | R55: =IF(F55>$M55,0,1) -> 0 | S55: =IF(K55>$M55,0,1) -> 1 | V55: =IF(N55=O55,1,0) -> 0 | Y55: =IF(P55=Q55,1,0) -> 0
A56: =MIN(C56,H56) -> 374.6 | B56: 15x4C | C56: 374.6 | D56: 604.75 | E56: 907.73 | F56: 353.4 | H56: 580.62 | I56: 749.19 | J56: 845.16 | K56: 560.07 | L56: =MIN(D56,I56) -> 604.75 | M56: =MIN(F56,K56) -> 353.4 | N56: =IF(C56>$A56,0,1) -> 1 | O56: =IF(H56>$A56,0,1) -> 0 | P56: =IF(D56>$L56,0,1) -> 1 | Q56: =IF(I56>$L56,0,1) -> 0 | R56: =IF(F56>$M56,0,1) -> 1 | S56: =IF(K56>$M56,0,1) -> 0 | V56: =IF(N56=O56,1,0) -> 0 | Y56: =IF(P56=Q56,1,0) -> 0
A57: =MIN(C57,H57) -> 29626.5 | B57: 20x3C | C57: 29764.93 | D57: 30018.93 | E57: 784.09 | F57: 29791.1 | H57: 29626.5 | I57: 29963 | J57: 1135.04 | K57: 29695.53 | L57: =MIN(D57,I57) -> 29963 | M57: =MIN(F57,K57) -> 29695.53 | N57: =IF(C57>$A57,0,1) -> 0 | O57: =IF(H57>$A57,0,1) -> 1 | P57: =IF(D57>$L57,0,1) -> 0 | Q57: =IF(I57>$L57,0,1) -> 1 | R57: =IF(F57>$M57,0,1) -> 0 | S57: =IF(K57>$M57,0,1) -> 1 | V57: =IF(N57=O57,1,0) -> 0 | Y57: =IF(P57=Q57,1,0) -> 0
A58: =MIN(C58,H58) -> 5248.03 | B58: 20x4C | C58: 5248.03 | D58: 5707.41 | E58: 305.23 | F58: 5193.2 | H58: 5363.9 | I58: 5826.31 | J58: 286.07 | K58: 5346.27 | L58: =MIN(D58,I58) -> 5707.41 | M58: =MIN(F58,K58) -> 5193.2 | N58: =IF(C58>$A58,0,1) -> 1 | O58: =IF(H58>$A58,0,1) -> 0 | P58: =IF(D58>$L58,0,1) -> 1 | Q58: =IF(I58>$L58,0,1) -> 0 | R58: =IF(F58>$M58,0,1) -> 1 | S58: =IF(K58>$M58,0,1) -> 0 | V58: =IF(N58=O58,1,0) -> 0 | Y58: =IF(P58=Q58,1,0) -> 0
A59: =MIN(C59,H59) -> 82114.78 | B59: 25x3C | C59: 82328.8 | D59: 82564.93 | E59: 1060.08 | F59: 82390.3 | H59: 82114.78 | I59: 82754.49 | J59: 777.46 | K59: 82179.4 | L59: =MIN(D59,I59) -> 82564.93 | M59: =MIN(F59,K59) -> 82179.4 | N59: =IF(C59>$A59,0,1) -> 0 | O59: =IF(H59>$A59,0,1) -> 1 | P59: =IF(D59>$L59,0,1) -> 1 | Q59: =IF(I59>$L59,0,1) -> 0 | R59: =IF(F59>$M59,0,1) -> 0 | S59: =IF(K59>$M59,0,1) -> 1 | V59: =IF(N59=O59,1,0) -> 0 | Y59: =IF(P59=Q59,1,0) -> 0
A60: =MIN(C60,H60) -> 43721.55 | B60: 25x5C | C60: 43721.55 | D60: 44134.35 | E60: 1488.81 | F60: 43829.2 | H60: 43771.41 | I60: 44326.43 | J60: 1504.67 | K60: 43834.52 | L60: =MIN(D60,I60) -> 44134.35 | M60: =MIN(F60,K60) -> 43829.2 | N60: =IF(C60>$A60,0,1) -> 1 | O60: =IF(H60>$A60,0,1) -> 0 | P60: =IF(D60>$L60,0,1) -> 1 | Q60: =IF(I60>$L60,0,1) -> 0 | R60: =IF(F60>$M60,0,1) -> 1 | S60: =IF(K60>$M60,0,1) -> 0 | V60: =IF(N60=O60,1,0) -> 0 | Y60: =IF(P60=Q60,1,0) -> 0
A61: =MIN(C61,H61) -> 121351.14 | B61: 28x3C | C61: 121351.14 | D61: 122520.48 | E61: 1198 | F61: 121631.9 | H61: 121554.89 | I61: 122973.3 | J61: 1120.04 | K61: 121856.18 | L61: =MIN(D61,I61) -> 122520.48 | M61: =MIN(F61,K61) -> 121631.9 | N61: =IF(C61>$A61,0,1) -> 1 | O61: =IF(H61>$A61,0,1) -> 0 | P61: =IF(D61>$L61,0,1) -> 1 | Q61: =IF(I61>$L61,0,1) -> 0 | R61: =IF(F61>$M61,0,1) -> 1 | S61: =IF(K61>$M61,0,1) -> 0 | V61: =IF(N61=O61,1,0) -> 0 | Y61: =IF(P61=Q61,1,0) -> 0
A62: =MIN(C62,H62) -> 42243.96 | B62: 28x5C | C62: 42243.96 | D62: 43088.97 | E62: 1425.05 | F62: 42307.7 | H62: 43610.6 | I62: 44190 | J62: 1316.74 | K62: 43692.1 | L62: =MIN(D62,I62) -> 43088.97 | M62: =MIN(F62,K62) -> 42307.7 | N62: =IF(C62>$A62,0,1) -> 1 | O62: =IF(H62>$A62,0,1) -> 0 | P62: =IF(D62>$L62,0,1) -> 1 | Q62: =IF(I62>$L62,0,1) -> 0 | R62: =IF(F62>$M62,0,1) -> 1 | S62: =IF(K62>$M62,0,1) -> 0 | V62: =IF(N62=O62,1,0) -> 0 | Y62: =IF(P62=Q62,1,0) -> 0
...

Sheet resultOnlatexABC16Dec24
D4: SimHGS | L4: Tsim | T4: SBDF100 | AB4: SBDB100
D5: Best | F5: Avg | H5: T | J5: E | L5: Best | N5: Avg | P5: T | R5: E | T5: Best | V5: Avg | X5: T | Z5: E | AB5: Best | AD5: Avg | AF5: T | AH5: E
A6: =MIN(D6,L6,T6,AB6) -> 5441.25 | B6: 10x3A | C6: & | D6: =D89 -> 5441.25 | E6: & | F6: =E89 -> 5441.25 | G6: & | H6: =F89 -> 8.76 | I6: & | J6: =G89 -> 5443.3 | K6: & | L6: =I89 -> 6181.1 | M6: & | N6: =J89 -> 6181.15 | O6: & | P6: =K89 -> 0.14 | Q6: & | R6: =L89 -> 6150.9 | S6: & | T6: =M89 -> 5443.2 | U6: & | V6: =N89 -> 5450.73 | W6: & | X6: =O89 -> 21.38 | Y6: & | Z6: =P89 -> 5445.3 | AA6: & | AB6: =Q89 -> 5443.2 | AC6: & | AD6: =R89 -> 5454.89 | AE6: & | AF6: =S89 -> 60.11 | AG6: & | AH6: =T89 -> 5445.3 | AI6: \\ | AO6: Best | AW6: AvgObj
A7: =MIN(D7,L7,T7,AB7) -> 7533.59 | B7: 10x4A | C7: & | D7: =D90 -> 7533.59 | E7: & | F7: =E90 -> 7533.59 | G7: & | H7: =F90 -> 2.09 | I7: & | J7: =G90 -> 7528.4 | K7: & | L7: =I90 -> 7744.4 | M7: & | N7: =J90 -> 7744.35 | O7: & | P7: =K90 -> 6.08 | Q7: & | R7: =L90 -> 7725.7 | S7: & | T7: =M90 -> 7533.6 | U7: & | V7: =N90 -> 7533.63 | W7: & | X7: =O90 -> 6.21 | Y7: & | Z7: =P90 -> 7528.4 | AA7: & | AB7: =Q90 -> 7533.6 | AC7: & | AD7: =R90 -> 7533.63 | AE7: & | AF7: =S90 -> 11.06 | AG7: & | AH7: =T90 -> 7528.4 | AI7: \\ | AO7: #Wins | AQ7: #Ties | AS7: #losses | AU7: p-value | AV7: & | AW7: #Wins | AY7: #Ties | BA7: #losses | BC7: p-value
A8: =MIN(D8,L8,T8,AB8) -> 10019 | B8: 15x3A | C8: & | D8: =D91 -> 10019 | E8: & | F8: =E91 -> 10019 | G8: & | H8: =F91 -> 14.54 | I8: & | J8: =G91 -> 10019 | K8: & | L8: =I91 -> 10027.9 | M8: & | N8: =J91 -> 10027.93 | O8: & | P8: =K91 -> 103.25 | Q8: & | R8: =L91 -> 10027.9 | S8: & | T8: =M91 -> 10023.1 | U8: & | V8: =N91 -> 10023.54 | W8: & | X8: =O91 -> 4.37 | Y8: & | Z8: =P91 -> 10020.9 | AA8: & | AB8: =Q91 -> 10023.1 | AC8: & | AD8: =R91 -> 10024.4 | AE8: & | AF8: =S91 -> 11.01 | AG8: & | AH8: =T91 -> 10020.9 | AI8: \\ | AK8: \multirow{4}{*}{SetA} | AL8: & | AM8: SimHGS vs. TSim | AN8: & | AO8: =SUMPRODUCT(--(D6:D29<L6:L29)) -> 24 | AP8: & | AQ8: =SUMPRODUCT(--(D6:D29=L6:L29)) -> 0 | AR8: & | AS8: =SUMPRODUCT(--(D6:D29>L6:L29)) -> 0 | AT8: & | AU8: 1.192093e-07 | AV8: & | AW8: =SUMPRODUCT(--(F6:F29<N6:N29)) -> 24 | AX8: & | AY8: =SUMPRODUCT(--(F6:F29=N6:N29)) -> 0 | AZ8: & | BA8: =SUMPRODUCT(--(F6:F29>N6:N29)) -> 0 | BB8: & | BC8: 1.192093e-07 | BD8: \\
A9: =MIN(D9,L9,T9,AB9) -> 13226.2 | B9: 15x4A | C9: & | D9: =D92 -> 13226.2 | E9: & | F9: =E92 -> 13226.2 | G9: & | H9: =F92 -> 42.53 | I9: & | J9: =G92 -> 13227.1 | K9: & | L9: =I92 -> 13751.4 | M9: & | N9: =J92 -> 13751.43 | O9: & | P9: =K92 -> 14.3 | Q9: & | R9: =L92 -> 13762 | S9: & | T9: =M92 -> 13238.3 | U9: & | V9: =N92 -> 13238.3 | W9: & | X9: =O92 -> 37.41 | Y9: & | Z9: =P92 -> 13238.1 | AA9: & | AB9: =Q92 -> 13238.3 | AC9: & | AD9: =R92 -> 13238.3 | AE9: & | AF9: =S92 -> 130.21 | AG9: & | AH9: =T92 -> 13238.1 | AI9: \\ | AL9: & | AM9: SimHGS vs. SBDF100 | AN9: & | AO9: =SUMPRODUCT(--(D6:D29<T6:T29)) -> 23 | AP9: & | AQ9: =SUMPRODUCT(--(D6:D29=T6:T29)) -> 1 | AR9: & | AS9: =SUMPRODUCT(--(D6:D29>T6:T29)) -> 0 | AT9: & | AU9: 2.384186e-07 | AV9: & | AW9: =SUMPRODUCT(--(F6:F29<V6:V29)) -> 23 | AX9: & | AY9: =SUMPRODUCT(--(F6:F29=V6:V29)) -> 1 | AZ9: & | BA9: =SUMPRODUCT(--(F6:F29>V6:V29)) -> 0 | BB9: & | BC9: 1.192093e-07 | BD9: \\
A10: =MIN(D10,L10,T10,AB10) -> 17695 | B10: 20x3A | C10: & | D10: =D93 -> 17695 | E10: & | F10: =E93 -> 17695 | G10: & | H10: =F93 -> 128.78 | I10: & | J10: =G93 -> 17695 | K10: & | L10: =I93 -> 18191.5 | M10: & | N10: =J93 -> 18219.96 | O10: & | P10: =K93 -> 178.79 | Q10: & | R10: =L93 -> 18191.4 | S10: & | T10: =M93 -> 17695 | U10: & | V10: =N93 -> 17695 | W10: & | X10: =O93 -> 88.32 | Y10: & | Z10: =P93 -> 17695 | AA10: & | AB10: =Q93 -> 17695 | AC10: & | AD10: =R93 -> 17695 | AE10: & | AF10: =S93 -> 296.08 | AG10: & | AH10: =T93 -> 17695 | AI10: \\ | AL10: & | AM10: SimHGS vs. SBDB100 | AN10: & | AO10: =SUMPRODUCT(--(D6:D29<AB6:AB29)) -> 23 | AP10: & | AQ10: =SUMPRODUCT(--(D6:D29=AB6:AB29)) -> 1 | AR10: & | AS10: =SUMPRODUCT(--(D6:D29>AB6:AB29)) -> 0 | AT10: & | AU10: 2.384186e-07 | AV10: & | AW10: =SUMPRODUCT(--(F6:F29<AD6:AD29)) -> 23 | AX10: & | AY10: =SUMPRODUCT(--(F6:F29=AD6:AD29)) -> 1 | AZ10: & | BA10: =SUMPRODUCT(--(F6:F29>AD6:AD29)) -> 0 | BB10: & | BC10: 2.384186e-07 | BD10: \\
A11: =MIN(D11,L11,T11,AB11) -> 17805.75 | B11: 20x4A | C11: & | D11: =D94 -> 17805.75 | E11: & | F11: =E94 -> 17805.75 | G11: & | H11: =F94 -> 176.61 | I11: & | J11: =G94 -> 17794.8 | K11: & | L11: =I94 -> 18087.5 | M11: & | N11: =J94 -> 18092.65 | O11: & | P11: =K94 -> 614.66 | Q11: & | R11: =L94 -> 18075.3 | S11: & | T11: =M94 -> 17805.8 | U11: & | V11: =N94 -> 17805.81 | W11: & | X11: =O94 -> 506.49 | Y11: & | Z11: =P94 -> 17794.8 | AA11: & | AB11: =Q94 -> 17805.8 | AC11: & | AD11: =R94 -> 17806.06 | AE11: & | AF11: =S94 -> 519.94 | AG11: & | AH11: =T94 -> 17794.8 | AI11: \\ | AL11: & | AM11: SimHGS vs. All | AN11: & | AO11: 23 | AP11: & | AQ11: 1 | AR11: & | AS11: 0 | AT11: & | AU11: \-- | AV11: & | AW11: 23 | AX11: & | AY11: 1 | AZ11: & | BA11: 0 | BB11: & | BC11: \-- | BD11: \\
A12: =MIN(D12,L12,T12,AB12) -> 70463.51 | B12: 25x3A | C12: & | D12: =D95 -> 70463.51 | E12: & | F12: =E95 -> 70464.31 | G12: & | H12: =F95 -> 968.3 | I12: & | J12: =G95 -> 70465.9 | K12: & | L12: =I95 -> 70666.8 | M12: & | N12: =J95 -> 70682.86 | O12: & | P12: =K95 -> 713.61 | Q12: & | R12: =L95 -> 70662.4 | S12: & | T12: =M95 -> 70469.8 | U12: & | V12: =N95 -> 70472.26 | W12: & | X12: =O95 -> 464.07 | Y12: & | Z12: =P95 -> 70471.3 | AA12: & | AB12: =Q95 -> 70469.8 | AC12: & | AD12: =R95 -> 70472.32 | AE12: & | AF12: =S95 -> 752.57 | AG12: & | AH12: =T95 -> 70471.3 | AI12: \\ | AK12: \hline
A13: =MIN(D13,L13,T13,AB13) -> 35221.33 | B13: 25x5A | C13: & | D13: =D96 -> 35221.33 | E13: & | F13: =E96 -> 35222.38 | G13: & | H13: =F96 -> 1192.27 | I13: & | J13: =G96 -> 35227.2 | K13: & | L13: =I96 -> 35920.2 | M13: & | N13: =J96 -> 36061.84 | O13: & | P13: =K96 -> 894.81 | Q13: & | R13: =L96 -> 35925.5 | S13: & | T13: =M96 -> 35223.1 | U13: & | V13: =N96 -> 35227.2 | W13: & | X13: =O96 -> 927.08 | Y13: & | Z13: =P96 -> 35231.3 | AA13: & | AB13: =Q96 -> 35224.8 | AC13: & | AD13: =R96 -> 35232.45 | AE13: & | AF13: =S96 -> 1404.78 | AG13: & | AH13: =T96 -> 35231.8 | AI13: \\ | AK13: \multirow{4}{*}{SetB} | AL13: & | AM13: SimHGS vs. TSim | AN13: & | AO13: {=SUMPRODUCT(--(D31:D54<L31:L54))} -> 24 | AP13: & | AQ13: {=SUMPRODUCT(--(D31:D54=L31:L54))} -> 0 | AR13: & | AS13: {=SUMPRODUCT(--(D31:D54>L31:L54))} -> 0 | AT13: & | AU13: 1.192093e-07 | AV13: & | AW13: {=SUMPRODUCT(--(F31:F54<N31:N54))} -> 24 | AX13: & | AY13: {=SUMPRODUCT(--(F31:F54=N31:N54))} -> 0 | AZ13: & | BA13: {=SUMPRODUCT(--(F31:F54>N31:N54))} -> 0 | BB13: & | BC13: 1.192093e-07 | BD13: \\
A14: =MIN(D14,L14,T14,AB14) -> 65003.48 | B14: 28x3A | C14: & | D14: =D97 -> 65003.48 | E14: & | F14: =E97 -> 65003.48 | G14: & | H14: =F97 -> 304.02 | I14: & | J14: =G97 -> 65050.5 | K14: & | L14: =I97 -> 65435.9 | M14: & | N14: =J97 -> 65436.55 | O14: & | P14: =K97 -> 210.99 | Q14: & | R14: =L97 -> 65433.4 | S14: & | T14: =M97 -> 65004 | U14: & | V14: =N97 -> 65013.7 | W14: & | X14: =O97 -> 736.82 | Y14: & | Z14: =P97 -> 65011.4 | AA14: & | AB14: =Q97 -> 65004 | AC14: & | AD14: =R97 -> 65009.05 | AE14: & | AF14: =S97 -> 803.23 | AG14: & | AH14: =T97 -> 65011.4 | AI14: \\ | AL14: & | AM14: SimHGS vs. SBDF100 | AN14: & | AO14: {=SUMPRODUCT(--(D31:D54<T31:T54))} -> 24 | AP14: & | AQ14: {=SUMPRODUCT(--(D31:D54=T31:T54))} -> 0 | AR14: & | AS14: {=SUMPRODUCT(--(D31:D54>T31:T54))} -> 0 | AT14: & | AU14: 1.192093e-07 | AV14: & | AW14: {=SUMPRODUCT(--(F31:F54<V31:V54))} -> 24 | AX14: & | AY14: {=SUMPRODUCT(--(F31:F54=V31:V54))} -> 0 | AZ14: & | BA14: {=SUMPRODUCT(--(F31:F54>V31:V54))} -> 0 | BB14: & | BC14: 1.192093e-07 | BD14: \\
A15: =MIN(D15,L15,T15,AB15) -> 63293.84 | B15: 28x5A | C15: & | D15: =D98 -> 63293.84 | E15: & | F15: =E98 -> 63297.9 | G15: & | H15: =F98 -> 829.87 | I15: & | J15: =G98 -> 63297 | K15: & | L15: =I98 -> 64528.8 | M15: & | N15: =J98 -> 64716.69 | O15: & | P15: =K98 -> 1174.71 | Q15: & | R15: =L98 -> 64533.1 | S15: & | T15: =M98 -> 63297.1 | U15: & | V15: =N98 -> 63311.6 | W15: & | X15: =O98 -> 1350.66 | Y15: & | Z15: =P98 -> 63301.5 | AA15: & | AB15: =Q98 -> 63299.6 | AC15: & | AD15: =R98 -> 63332.74 | AE15: & | AF15: =S98 -> 1234.24 | AG15: & | AH15: =T98 -> 63303.6 | AI15: \\ | AL15: & | AM15: SimHGS vs. SBDB100 | AN15: & | AO15: {=SUMPRODUCT(--(D31:D54<AB31:AB54))} -> 24 | AP15: & | AQ15: {=SUMPRODUCT(--(D31:D54=AB31:AB54))} -> 0 | AR15: & | AS15: {=SUMPRODUCT(--(D31:D54>AB31:AB54))} -> 0 | AT15: & | AU15: 1.192093e-07 | AV15: & | AW15: {=SUMPRODUCT(--(F31:F54<AD31:AD54))} -> 24 | AX15: & | AY15: {=SUMPRODUCT(--(F31:F54=AD31:AD54))} -> 0 | AZ15: & | BA15: {=SUMPRODUCT(--(F31:F54>AD31:AD54))} -> 0 | BB15: & | BC15: 1.192093e-07 | BD15: \\
A16: =MIN(D16,L16,T16,AB16) -> 53201.45 | B16: 30x6A | C16: & | D16: =D99 -> 53201.45 | E16: & | F16: =E99 -> 53207.38 | G16: & | H16: =F99 -> 1145.47 | I16: & | J16: =G99 -> 53200.2 | K16: & | L16: =I99 -> 54360.9 | M16: & | N16: =J99 -> 54472.18 | O16: & | P16: =K99 -> 1048.7 | Q16: & | R16: =L99 -> 54366.7 | S16: & | T16: =M99 -> 53217.4 | U16: & | V16: =N99 -> 53231.42 | W16: & | X16: =O99 -> 1539.94 | Y16: & | Z16: =P99 -> 53226.5 | AA16: & | AB16: =Q99 -> 53231.3 | AC16: & | AD16: =R99 -> 53250.43 | AE16: & | AF16: =S99 -> 1518.5 | AG16: & | AH16: =T99 -> 53237.4 | AI16: \\ | AL16: & | AM16: SimHGS vs. All | AN16: & | AO16: 24 | AP16: & | AQ16: 0 | AR16: & | AS16: 0 | AT16: & | AU16: \-- | AV16: & | AW16: 24 | AX16: & | AY16: 0 | AZ16: & | BA16: 0 | BB16: & | BC16: \-- | BD16: \\
A17: =MIN(D17,L17,T17,AB17) -> 61352.43 | B17: 30x8A | C17: & | D17: =D100 -> 61352.43 | E17: & | F17: =E100 -> 61359.5 | G17: & | H17: =F100 -> 1062.79 | I17: & | J17: =G100 -> 61362.3 | K17: & | L17: =I100 -> 62634.9 | M17: & | N17: =J100 -> 62919.44 | O17: & | P17: =K100 -> 1021.26 | Q17: & | R17: =L100 -> 62670.2 | S17: & | T17: =M100 -> 61382.6 | U17: & | V17: =N100 -> 61638.83 | W17: & | X17: =O100 -> 1489.04 | Y17: & | Z17: =P100 -> 61390.9 | AA17: & | AB17: =Q100 -> 61410.1 | AC17: & | AD17: =R100 -> 61664.57 | AE17: & | AF17: =S100 -> 1575.11 | AG17: & | AH17: =T100 -> 61428.1 | AI17: \\ | AK17: \hline
A18: =MIN(D18,L18,T18,AB18) -> 88253.35 | B18: 35x6A | C18: & | D18: =D101 -> 88253.35 | E18: & | F18: =E101 -> 88419.96 | G18: & | H18: =F101 -> 1475.47 | I18: & | J18: =G101 -> 88276.9 | K18: & | L18: =I101 -> 89484.8 | M18: & | N18: =J101 -> 89661.75 | O18: & | P18: =K101 -> 1232 | Q18: & | R18: =L101 -> 89494.4 | S18: & | T18: =M101 -> 88406.9 | U18: & | V18: =N101 -> 88635.54 | W18: & | X18: =O101 -> 1608.49 | Y18: & | Z18: =P101 -> 88439.3 | AA18: & | AB18: =Q101 -> 88648.5 | AC18: & | AD18: =R101 -> 88768.15 | AE18: & | AF18: =S101 -> 1499.46 | AG18: & | AH18: =T101 -> 88651.6 | AI18: \\ | AK18: \multirow{4}{*}{SetC} | AL18: & | AM18: SimHGS vs. TSim | AN18: & | AO18: {=SUMPRODUCT(--(D56:D79<L56:L79))} -> 22 | AP18: & | AQ18: {=SUMPRODUCT(--(D56:D79=L56:L79))} -> 0 | AR18: & | AS18: {=SUMPRODUCT(--(D56:D79>L56:L79))} -> 2 | AT18: & | AU18: 2.980232e-06 | AV18: & | AW18: {=SUMPRODUCT(--(F56:F79<N56:N79))} -> 23 | AX18: & | AY18: {=SUMPRODUCT(--(F56:F79=N56:N79))} -> 0 | AZ18: & | BA18: {=SUMPRODUCT(--(F56:F79>N56:N79))} -> 1 | BB18: & | BC18: 5.960464e-07 | BD18: \\
A19: =MIN(D19,L19,T19,AB19) -> 83443.56 | B19: 35x8A | C19: & | D19: =D102 -> 83443.56 | E19: & | F19: =E102 -> 83487.84 | G19: & | H19: =F102 -> 1415.68 | I19: & | J19: =G102 -> 83429.3 | K19: & | L19: =I102 -> 84860.4 | M19: & | N19: =J102 -> 84914.83 | O19: & | P19: =K102 -> 1215.16 | Q19: & | R19: =L102 -> 84844.7 | S19: & | T19: =M102 -> 83640.7 | U19: & | V19: =N102 -> 83728.68 | W19: & | X19: =O102 -> 1557.19 | Y19: & | Z19: =P102 -> 83622.6 | AA19: & | AB19: =Q102 -> 83738.1 | AC19: & | AD19: =R102 -> 83832.77 | AE19: & | AF19: =S102 -> 1440.25 | AG19: & | AH19: =T102 -> 83713.3 | AI19: \\ | AL19: & | AM19: SimHGS vs. SBDF100 | AN19: & | AO19: {=SUMPRODUCT(--(D56:D79<T56:T79))} -> 20 | AP19: & | AQ19: {=SUMPRODUCT(--(D56:D79=T56:T79))} -> 1 | AR19: & | AS19: {=SUMPRODUCT(--(D56:D79>T56:T79))} -> 3 | AT19: & | AU19: 3.015995e-05 | AV19: & | AW19: {=SUMPRODUCT(--(F56:F79<V56:V79))} -> 23 | AX19: & | AY19: {=SUMPRODUCT(--(F56:F79=V56:V79))} -> 0 | AZ19: & | BA19: {=SUMPRODUCT(--(F56:F79>V56:V79))} -> 1 | BB19: & | BC19: 5.960464e-07 | BD19: \\
A20: =MIN(D20,L20,T20,AB20) -> 107222.34 | B20: 40x6A | C20: & | D20: =D103 -> 107222.34 | E20: & | F20: =E103 -> 107306.55 | G20: & | H20: =F103 -> 1623.5 | I20: & | J20: =G103 -> 107293.3 | K20: & | L20: =I103 -> 109285.7 | M20: & | N20: =J103 -> 109760.73 | O20: & | P20: =K103 -> 1641.64 | Q20: & | R20: =L103 -> 109363.2 | S20: & | T20: =M103 -> 107351.6 | U20: & | V20: =N103 -> 107708.26 | W20: & | X20: =O103 -> 1493.44 | Y20: & | Z20: =P103 -> 107430.5 | AA20: & | AB20: =Q103 -> 107696 | AC20: & | AD20: =R103 -> 107896.96 | AE20: & | AF20: =S103 -> 1289.25 | AG20: & | AH20: =T103 -> 107776 | AI20: \\ | AL20: & | AM20: SimHGS vs. SBDB100 | AN20: & | AO20: {=SUMPRODUCT(--(D56:D79<AB56:AB79))} -> 21 | AP20: & | AQ20: {=SUMPRODUCT(--(D56:D79=AB56:AB79))} -> 0 | AR20: & | AS20: {=SUMPRODUCT(--(D56:D79>AB56:AB79))} -> 3 | AT20: & | AU20: 2.467632e-05 | AV20: & | AW20: {=SUMPRODUCT(--(F56:F79<AD56:AD79))} -> 23 | AX20: & | AY20: {=SUMPRODUCT(--(F56:F79=AD56:AD79))} -> 0 | AZ20: & | BA20: {=SUMPRODUCT(--(F56:F79>AD56:AD79))} -> 1 | BB20: & | BC20: 5.960464e-07 | BD20: \\
A21: =MIN(D21,L21,T21,AB21) -> 118623.58 | B21: 40x8A | C21: & | D21: =D104 -> 118623.58 | E21: & | F21: =E104 -> 118892.14 | G21: & | H21: =F104 -> 1577.57 | I21: & | J21: =G104 -> 118657 | K21: & | L21: =I104 -> 120417.4 | M21: & | N21: =J104 -> 120889.36 | O21: & | P21: =K104 -> 1316.4 | Q21: & | R21: =L104 -> 120436.7 | S21: & | T21: =M104 -> 119144.1 | U21: & | V21: =N104 -> 119248.44 | W21: & | X21: =O104 -> 1449.91 | Y21: & | Z21: =P104 -> 119161.4 | AA21: & | AB21: =Q104 -> 119199.8 | AC21: & | AD21: =R104 -> 119429.96 | AE21: & | AF21: =S104 -> 1417.97 | AG21: & | AH21: =T104 -> 119203 | AI21: \\ | AL21: & | AM21: SimHGS vs. All | AN21: & | AO21: 19 | AP21: & | AQ21: 0 | AR21: & | AS21: 5 | AT21: & | AU21: \-- | AV21: & | AW21: 22 | AX21: & | AY21: 0 | AZ21: & | BA21: 2 | BB21: & | BC21: \-- | BD21: \\
A22: =MIN(D22,L22,T22,AB22) -> 259656.7 | B22: 50x6A | C22: & | D22: =D105 -> 259656.7 | E22: & | F22: =E105 -> 259869.59 | G22: & | H22: =F105 -> 1653.67 | I22: & | J22: =G105 -> 259652.1 | K22: & | L22: =I105 -> 260943.6 | M22: & | N22: =J105 -> 261216.01 | O22: & | P22: =K105 -> 1657.82 | Q22: & | R22: =L105 -> 260904.7 | S22: & | T22: =M105 -> 260061.1 | U22: & | V22: =N105 -> 260153.49 | W22: & | X22: =O105 -> 1296.87 | Y22: & | Z22: =P105 -> 260048 | AA22: & | AB22: =Q105 -> 260151.2 | AC22: & | AD22: =R105 -> 260237.58 | AE22: & | AF22: =S105 -> 673.55 | AG22: & | AH22: =T105 -> 260146.8 | AI22: \\
A23: =MIN(D23,L23,T23,AB23) -> 168321.2 | B23: 50x8A | C23: & | D23: =D106 -> 168321.2 | E23: & | F23: =E106 -> 168378.93 | G23: & | H23: =F106 -> 1522.26 | I23: & | J23: =G106 -> 168355.2 | K23: & | L23: =I106 -> 171459.9 | M23: & | N23: =J106 -> 171710.13 | O23: & | P23: =K106 -> 1577.1 | Q23: & | R23: =L106 -> 171457.3 | S23: & | T23: =M106 -> 168610.9 | U23: & | V23: =N106 -> 168956.81 | W23: & | X23: =O106 -> 1617.92 | Y23: & | Z23: =P106 -> 168647.5 | AA23: & | AB23: =Q106 -> 169022.6 | AC23: & | AD23: =R106 -> 169352.54 | AE23: & | AF23: =S106 -> 1092.49 | AG23: & | AH23: =T106 -> 169034.8 | AI23: \\
A24: =MIN(D24,L24,T24,AB24) -> 256174.84 | B24: 60x8A | C24: & | D24: =D107 -> 256174.84 | E24: & | F24: =E107 -> 256684.28 | G24: & | H24: =F107 -> 1603.11 | I24: & | J24: =G107 -> 256202 | K24: & | L24: =I107 -> 260713.3 | M24: & | N24: =J107 -> 261217.1 | O24: & | P24: =K107 -> 1674.77 | Q24: & | R24: =L107 -> 260810 | S24: & | T24: =M107 -> 258085.3 | U24: & | V24: =N107 -> 258651.96 | W24: & | X24: =O107 -> 540.36 | Y24: & | Z24: =P107 -> 258129.4 | AA24: & | AB24: =Q107 -> 258085.3 | AC24: & | AD24: =R107 -> 258815.87 | AE24: & | AF24: =S107 -> 1164.96 | AG24: & | AH24: =T107 -> 258129.4 | AI24: \\
A25: =MIN(D25,L25,T25,AB25) -> 258497.09 | B25: 60x10A | C25: & | D25: =D108 -> 258497.09 | E25: & | F25: =E108 -> 258632.3 | G25: & | H25: =F108 -> 1644.68 | I25: & | J25: =G108 -> 258447.2 | K25: & | L25: =I108 -> 263020.8 | M25: & | N25: =J108 -> 263635.56 | O25: & | P25: =K108 -> 1680.58 | Q25: & | R25: =L108 -> 263001 | S25: & | T25: =M108 -> 260783.5 | U25: & | V25: =N108 -> 261486.01 | W25: & | X25: =O108 -> 1148.46 | Y25: & | Z25: =P108 -> 260765.7 | AA25: & | AB25: =Q108 -> 260783.5 | AC25: & | AD25: =R108 -> 261695.93 | AE25: & | AF25: =S108 -> 1036 | AG25: & | AH25: =T108 -> 260765.7 | AI25: \\
A26: =MIN(D26,L26,T26,AB26) -> 554099.42 | B26: 80x8A | C26: & | D26: =D109 -> 554099.42 | E26: & | F26: =E109 -> 554848.92 | G26: & | H26: =F109 -> 1300.46 | I26: & | J26: =G109 -> 554057.4 | K26: & | L26: =I109 -> 560289.4 | M26: & | N26: =J109 -> 561870.42 | O26: & | P26: =K109 -> 1216.8 | Q26: & | R26: =L109 -> 560090.5 | S26: & | T26: =M109 -> 555576.9 | U26: & | V26: =N109 -> 555858.18 | W26: & | X26: =O109 -> 1258.31 | Y26: & | Z26: =P109 -> 555483.2 | AA26: & | AB26: =Q109 -> 555576.9 | AC26: & | AD26: =R109 -> 556354.18 | AE26: & | AF26: =S109 -> 1403.34 | AG26: & | AH26: =T109 -> 555483.2 | AI26: \\
A27: =MIN(D27,L27,T27,AB27) -> 373005.98 | B27: 80x10A | C27: & | D27: =D110 -> 373005.98 | E27: & | F27: =E110 -> 374262.99 | G27: & | H27: =F110 -> 1365.15 | I27: & | J27: =G110 -> 373042.9 | K27: & | L27: =I110 -> 383192.8 | M27: & | N27: =J110 -> 384059.22 | O27: & | P27: =K110 -> 1112.27 | Q27: & | R27: =L110 -> 383124.1 | S27: & | T27: =M110 -> 376213.5 | U27: & | V27: =N110 -> 377380.94 | W27: & | X27: =O110 -> 1468.63 | Y27: & | Z27: =P110 -> 376286 | AA27: & | AB27: =Q110 -> 377562.9 | AC27: & | AD27: =R110 -> 378674.32 | AE27: & | AF27: =S110 -> 1921.08 | AG27: & | AH27: =T110 -> 377586.2 | AI27: \\
A28: =MIN(D28,L28,T28,AB28) -> 773276.74 | B28: 100x10A | C28: & | D28: =D111 -> 773276.74 | E28: & | F28: =E111 -> 774292.47 | G28: & | H28: =F111 -> 620.95 | I28: & | J28: =G111 -> 773151.4 | K28: & | L28: =I111 -> 783806.3 | M28: & | N28: =J111 -> 785425.31 | O28: & | P28: =K111 -> 895.39 | Q28: & | R28: =L111 -> 783624.9 | S28: & | T28: =M111 -> 775503.2 | U28: & | V28: =N111 -> 777986.22 | W28: & | X28: =O111 -> 1945.98 | Y28: & | Z28: =P111 -> 775483.1 | AA28: & | AB28: =Q111 -> 776606.7 | AC28: & | AD28: =R111 -> 780047.99 | AE28: & | AF28: =S111 -> 2469.82 | AG28: & | AH28: =T111 -> 776564.6 | AI28: \\
A29: =MIN(D29,L29,T29,AB29) -> 749159.93 | B29: 100x15A | C29: & | D29: =D112 -> 749159.93 | E29: & | F29: =E112 -> 751312.57 | G29: & | H29: =F112 -> 1347.21 | I29: & | J29: =G112 -> 749120 | K29: & | L29: =I112 -> 762277.7 | M29: & | N29: =J112 -> 764966.46 | O29: & | P29: =K112 -> 1076.23 | Q29: & | R29: =L112 -> 762309.2 | S29: & | T29: =M112 -> 755112.7 | U29: & | V29: =N112 -> 762027.54 | W29: & | X29: =O112 -> 2575.53 | Y29: & | Z29: =P112 -> 755144.3 | AA29: & | AB29: =Q112 -> 765069.7 | AC29: & | AD29: =R112 -> 768359.59 | AE29: & | AF29: =S112 -> 3336.57 | AG29: & | AH29: =T112 -> 765039.5 | AI29: \\
A31: =MIN(D31,L31,T31,AB31) -> 17588.01 | B31: 10x3B | C31: & | D31: =D114 -> 17588.01 | E31: & | F31: =E114 -> 17588.01 | G31: & | H31: =F114 -> 24.11 | I31: & | J31: =G114 -> 17568.7 | K31: & | L31: =I114 -> 18470.4 | M31: & | N31: =J114 -> 18471.23 | O31: & | P31: =K114 -> 3.7 | Q31: & | R31: =L114 -> 18432.5 | S31: & | T31: =M114 -> 17588.5 | U31: & | V31: =N114 -> 17588.52 | W31: & | X31: =O114 -> 38.67 | Y31: & | Z31: =P114 -> 17567.9 | AA31: & | AB31: =Q114 -> 17588.5 | AC31: & | AD31: =R114 -> 17588.52 | AE31: & | AF31: =S114 -> 68.03 | AG31: & | AH31: =T114 -> 17567.9 | AI31: \\
A32: =MIN(D32,L32,T32,AB32) -> 24588.2 | B32: 10x4B | C32: & | D32: =D115 -> 24588.2 | E32: & | F32: =E115 -> 24588.2 | G32: & | H32: =F115 -> 5.91 | I32: & | J32: =G115 -> 24549.1 | K32: & | L32: =I115 -> 25312.8 | M32: & | N32: =J115 -> 25312.79 | O32: & | P32: =K115 -> 0.85 | Q32: & | R32: =L115 -> 25251.5 | S32: & | T32: =M115 -> 24592.1 | U32: & | V32: =N115 -> 24592.62 | W32: & | X32: =O115 -> 19.53 | Y32: & | Z32: =P115 -> 24554.8 | AA32: & | AB32: =Q115 -> 24592.1 | AC32: & | AD32: =R115 -> 24592.53 | AE32: & | AF32: =S115 -> 48.48 | AG32: & | AH32: =T115 -> 24554.8 | AI32: \\
A33: =MIN(D33,L33,T33,AB33) -> 37798.25 | B33: 15x3B | C33: & | D33: =D116 -> 37798.25 | E33: & | F33: =E116 -> 37798.93 | G33: & | H33: =F116 -> 934.95 | I33: & | J33: =G116 -> 37788.2 | K33: & | L33: =I116 -> 38652.6 | M33: & | N33: =J116 -> 38652.86 | O33: & | P33: =K116 -> 766.15 | Q33: & | R33: =L116 -> 38661.5 | S33: & | T33: =M116 -> 37801 | U33: & | V33: =N116 -> 37810.44 | W33: & | X33: =O116 -> 935.72 | Y33: & | Z33: =P116 -> 37788.8 | AA33: & | AB33: =Q116 -> 37799.6 | AC33: & | AD33: =R116 -> 37812 | AE33: & | AF33: =S116 -> 808.91 | AG33: & | AH33: =T116 -> 37788.9 | AI33: \\
A34: =MIN(D34,L34,T34,AB34) -> 50542.02 | B34: 15x4B | C34: & | D34: =D117 -> 50542.02 | E34: & | F34: =E117 -> 50549.05 | G34: & | H34: =F117 -> 1161.59 | I34: & | J34: =G117 -> 50566.1 | K34: & | L34: =I117 -> 51587.3 | M34: & | N34: =J117 -> 51587.26 | O34: & | P34: =K117 -> 214.84 | Q34: & | R34: =L117 -> 51619.6 | S34: & | T34: =M117 -> 50561.1 | U34: & | V34: =N117 -> 50589.46 | W34: & | X34: =O117 -> 955.5 | Y34: & | Z34: =P117 -> 50586.4 | AA34: & | AB34: =Q117 -> 50561.1 | AC34: & | AD34: =R117 -> 50600.12 | AE34: & | AF34: =S117 -> 1199.45 | AG34: & | AH34: =T117 -> 50586.4 | AI34: \\
... A79: =MIN(D79,L79,T79,AB79) -> 2239781.4 | B79: 100x15C | C79: & | D79: =D162 -> 2239781.4 | E79: & | F79: =E162 -> 2244887 | G79: & | H79: =F162 -> 868.4 | I79: & | J79: =G162 -> 2239764.5 | K79: & | L79: =I162 -> 2249184.4 | M79: & | N79: =J162 -> 2252212.5 | O79: & | P79: =K162 -> 1305.16 | Q79: & | R79: =L162 -> 2248922.3 | S79: & | T79: =M162 -> 2407298.8 | U79: & | V79: =N162 -> 2442178.6 | W79: & | X79: =O162 -> 6456.42 | Y79: & | Z79: =P162 -> 2406960.4 | AA79: & | AB79: =Q162 -> 2407298.8 | AC79: & | AD79: =R162 -> 2442178.6 | AE79: & | AF79: =S162 -> 9953.3 | AG79: & | AH79: =T162 -> 2406960.4 | AI79: \\
W88: Best | AC88: Avg
D89: 5441.25 | E89: 5441.25 | F89: 8.76 | G89: 5443.3 | H89: 5443.3 | I89: 6181.1 | J89: 6181.15 | K89: 0.14 | L89: 6150.9 | M89: 5443.2 | N89: 5450.73 | O89: 21.38 | P89: 5445.3 | Q89: 5443.2 | R89: 5454.89 | S89: 60.11 | T89: 5445.3 | W89: 0 | X89: 13.597059 | Y89: 0.035837354 | Z89: 0.035837354 | AC89: 0 | AD89: 13.597978 | AE89: 0.17422467 | AF89: 0.25067769
D90: 7533.59 | E90: 7533.59 | F90: 2.09 | G90: 7528.4 | H90: 7528.4 | I90: 7744.4 | J90: 7744.35 | K90: 6.08 | L90: 7725.7 | M90: 7533.6 | N90: 7533.63 | O90: 6.21 | P90: 7528.4 | Q90: 7533.6 | R90: 7533.63 | S90: 11.06 | T90: 7528.4 | W90: 0 | X90: 2.7982675 | Y90: 0.00013273884 | Z90: 0.00013273884 | AC90: 0 | AD90: 2.7976038 | AE90: 0.00053095536 | AF90: 0.00053095536
D91: 10019 | E91: 10019 | F91: 14.54 | G91: 10019 | H91: 10019 | I91: 10027.9 | J91: 10027.93 | K91: 103.25 | L91: 10027.9 | M91: 10023.1 | N91: 10023.54 | O91: 4.37 | P91: 10020.9 | Q91: 10023.1 | R91: 10024.4 | S91: 11.01 | T91: 10020.9 | W91: 0 | X91: 0.088831221 | Y91: 0.040922248 | Z91: 0.040922248 | AC91: 0 | AD91: 0.089130652 | AE91: 0.045313904 | AF91: 0.053897595
D92: 13226.2 | E92: 13226.2 | F92: 42.53 | G92: 13227.1 | H92: 13227.1 | I92: 13751.4 | J92: 13751.43 | K92: 14.3 | L92: 13762 | M92: 13238.3 | N92: 13238.3 | O92: 37.41 | P92: 13238.1 | Q92: 13238.3 | R92: 13238.3 | S92: 130.21 | T92: 13238.1 | W92: 0 | X92: 3.9709062 | Y92: 0.091485083 | Z92: 0.091485083 | AC92: 0 | AD92: 3.9711331 | AE92: 0.091485083 | AF92: 0.091485083
D93: 17695 | E93: 17695 | F93: 128.78 | G93: 17695 | H93: 17695 | I93: 18191.5 | J93: 18219.96 | K93: 178.79 | L93: 18191.4 | M93: 17695 | N93: 17695 | O93: 88.32 | P93: 17695 | Q93: 17695 | R93: 17695 | S93: 296.08 | T93: 17695 | W93: 0 | X93: 2.8058774 | Y93: 0 | Z93: 0 | AC93: 0 | AD93: 2.9667138 | AE93: 0 | AF93: 0
D94: 17805.75 | E94: 17805.75 | F94: 176.61 | G94: 17794.8 | H94: 17794.8 | I94: 18087.5 | J94: 18092.65 | K94: 614.66 | L94: 18075.3 | M94: 17805.8 | N94: 17805.81 | O94: 506.49 | P94: 17794.8 | Q94: 17805.8 | R94: 17806.06 | S94: 519.94 | T94: 17794.8 | W94: 0 | X94: 1.582354 | Y94: 0.00028080817 | Z94: 0.00028080817 | AC94: 0 | AD94: 1.6112773 | AE94: 0.0003369698 | AF94: 0.0017410106
D95: 70463.51 | E95: 70464.31 | F95: 968.3 | G95: 70465.9 | H95: 70465.9 | I95: 70666.8 | J95: 70682.86 | K95: 713.61 | L95: 70662.4 | M95: 70469.8 | N95: 70472.26 | O95: 464.07 | P95: 70471.3 | Q95: 70469.8 | R95: 70472.32 | S95: 752.57 | T95: 70471.3 | W95: 0 | X95: 0.28850394 | Y95: 0.0089266061 | Z95: 0.0089266061 | AC95: 0.0011353394 | AD95: 0.31129587 | AE95: 0.012417775 | AF95: 0.012502925
D96: 35221.33 | E96: 35222.38 | F96: 1192.27 | G96: 35227.2 | H96: 35227.2 | I96: 35920.2 | J96: 36061.84 | K96: 894.81 | L96: 35925.5 | M96: 35223.1 | N96: 35227.2 | O96: 927.08 | P96: 35231.3 | Q96: 35224.8 | R96: 35232.45 | S96: 1404.78 | T96: 35231.8 | W96: 0 | X96: 1.9842238 | Y96: 0.0050253639 | Z96: 0.0098519846 | AC96: 0.0029811481 | AD96: 2.3863664 | AE96: 0.016666037 | AF96: 0.031571778
...

Sheet resultOnlatex2ABC16Dec24
B1: 10x3A | C1: & | D1: =IF(E1=MIN(E1,Q1,AC1,AO1),"\textbf{","") -> \textbf{ | E1: =resultOnlatexABC16Dec24!D6 -> 5441.25 | F1: =IF(E1=MIN(E1,Q1,AC1,AO1),"}","") -> } | G1: & | H1: =IF(I1=MIN(I1,U1,AG1,AS1),"\textbf{","") -> \textbf{ | I1: =resultOnlatexABC16Dec24!F6 -> 5441.25 | J1: =IF(I1=MIN(I1,U1,AG1,AS1),"}","") -> } | K1: & | L1: =resultOnlatexABC16Dec24!H6 -> 8.76 | M1: & | N1: =resultOnlatexABC16Dec24!J6 -> 5443.3 | O1: & | P1: =IF(Q1=MIN(E1,Q1,AC1,AO1),"\textbf{","") | Q1: =resultOnlatexABC16Dec24!L6 -> 6181.1 | R1: =IF(Q1=MIN(E1,Q1,AC1,AO1),"}","") | S1: & | T1: =IF(U1=MIN(I1,U1,AG1,AS1),"\textbf{","") | U1: =resultOnlatexABC16Dec24!N6 -> 6181.15 | V1: =IF(U1=MIN(I1,U1,AG1,AS1),"}","") | W1: & | X1: =resultOnlatexABC16Dec24!P6 -> 0.14 | Y1: & | Z1: =resultOnlatexABC16Dec24!R6 -> 6150.9 | AA1: & | AB1: =IF(AC1=MIN(E1,Q1,AC1,AO1),"\textbf{","") | AC1: =resultOnlatexABC16Dec24!T6 -> 5443.2 | AD1: =IF(AC1=MIN(E1,Q1,AC1,AO1),"}","") | AE1: & | AF1: =IF(AG1=MIN(I1,U1,AG1,AS1),"\textbf{","") | AG1: =resultOnlatexABC16Dec24!V6 -> 5450.73 | AH1: =IF(AG1=MIN(I1,U1,AG1,AS1),"}","") | AI1: & | AJ1: =resultOnlatexABC16Dec24!X6 -> 21.38 | AK1: & | AL1: =resultOnlatexABC16Dec24!Z6 -> 5445.3 | AM1: & | AN1: =IF(AO1=MIN(E1,Q1,AC1,AO1),"\textbf{","") | AO1: =resultOnlatexABC16Dec24!AB6 -> 5443.2 | AP1: =IF(AO1=MIN(E1,Q1,AC1,AO1),"}","") | AQ1: & | AR1: =IF(AS1=MIN(I1,U1,AG1,AS1),"\textbf{","") | AS1: =resultOnlatexABC16Dec24!AD6 -> 5454.89 | AT1: =IF(AS1=MIN(I1,U1,AG1,AS1),"}","") | AU1: & | AV1: =resultOnlatexABC16Dec24!AF6 -> 60.11 | AW1: & | AX1: =resultOnlatexABC16Dec24!AH6 -> 5445.3 | AY1: \\
B2: 10x4A | C2: & | D2: =IF(E2=MIN(E2,Q2,AC2,AO2),"\textbf{","") -> \textbf{ | E2: =resultOnlatexABC16Dec24!D7 -> 7533.59 | F2: =IF(E2=MIN(E2,Q2,AC2,AO2),"}","") -> } | G2: & | H2: =IF(I2=MIN(I2,U2,AG2,AS2),"\textbf{","") -> \textbf{ | I2: =resultOnlatexABC16Dec24!F7 -> 7533.59 | J2: =IF(I2=MIN(I2,U2,AG2,AS2),"}","") -> } | K2: & | L2: =resultOnlatexABC16Dec24!H7 -> 2.09 | M2: & | N2: =resultOnlatexABC16Dec24!J7 -> 7528.4 | O2: & | P2: =IF(Q2=MIN(E2,Q2,AC2,AO2),"\textbf{","") | Q2: =resultOnlatexABC16Dec24!L7 -> 7744.4 | R2: =IF(Q2=MIN(E2,Q2,AC2,AO2),"}","") | S2: & | T2: =IF(U2=MIN(I2,U2,AG2,AS2),"\textbf{","") | U2: =resultOnlatexABC16Dec24!N7 -> 7744.35 | V2: =IF(U2=MIN(I2,U2,AG2,AS2),"}","") | W2: & | X2: =resultOnlatexABC16Dec24!P7 -> 6.08 | Y2: & | Z2: =resultOnlatexABC16Dec24!R7 -> 7725.7 | AA2: & | AB2: =IF(AC2=MIN(E2,Q2,AC2,AO2),"\textbf{","") | AC2: =resultOnlatexABC16Dec24!T7 -> 7533.6 | AD2: =IF(AC2=MIN(E2,Q2,AC2,AO2),"}","") | AE2: & | AF2: =IF(AG2=MIN(I2,U2,AG2,AS2),"\textbf{","") | AG2: =resultOnlatexABC16Dec24!V7 -> 7533.63 | AH2: =IF(AG2=MIN(I2,U2,AG2,AS2),"}","") | AI2: & | AJ2: =resultOnlatexABC16Dec24!X7 -> 6.21 | AK2: & | AL2: =resultOnlatexABC16Dec24!Z7 -> 7528.4 | AM2: & | AN2: =IF(AO2=MIN(E2,Q2,AC2,AO2),"\textbf{","") | AO2: =resultOnlatexABC16Dec24!AB7 -> 7533.6 | AP2: =IF(AO2=MIN(E2,Q2,AC2,AO2),"}","") | AQ2: & | AR2: =IF(AS2=MIN(I2,U2,AG2,AS2),"\textbf{","") | AS2: =resultOnlatexABC16Dec24!AD7 -> 7533.63 | AT2: =IF(AS2=MIN(I2,U2,AG2,AS2),"}","") | AU2: & | AV2: =resultOnlatexABC16Dec24!AF7 -> 11.06 | AW2: & | AX2: =resultOnlatexABC16Dec24!AH7 -> 7528.4 | AY2: \\
B3: 15x3A | C3: & | D3: =IF(E3=MIN(E3,Q3,AC3,AO3),"\textbf{","") -> \textbf{ | E3: =resultOnlatexABC16Dec24!D8 -> 10019 | F3: =IF(E3=MIN(E3,Q3,AC3,AO3),"}","") -> } | G3: & | H3: =IF(I3=MIN(I3,U3,AG3,AS3),"\textbf{","") -> \textbf{ | I3: =resultOnlatexABC16Dec24!F8 -> 10019 | J3: =IF(I3=MIN(I3,U3,AG3,AS3),"}","") -> } | K3: & | L3: =resultOnlatexABC16Dec24!H8 -> 14.54 | M3: & | N3: =resultOnlatexABC16Dec24!J8 -> 10019 | O3: & | P3: =IF(Q3=MIN(E3,Q3,AC3,AO3),"\textbf{","") | Q3: =resultOnlatexABC16Dec24!L8 -> 10027.9 | R3: =IF(Q3=MIN(E3,Q3,AC3,AO3),"}","") | S3: & | T3: =IF(U3=MIN(I3,U3,AG3,AS3),"\textbf{","") | U3: =resultOnlatexABC16Dec24!N8 -> 10027.93 | V3: =IF(U3=MIN(I3,U3,AG3,AS3),"}","") | W3: & | X3: =resultOnlatexABC16Dec24!P8 -> 103.25 | Y3: & | Z3: =resultOnlatexABC16Dec24!R8 -> 10027.9 | AA3: & | AB3: =IF(AC3=MIN(E3,Q3,AC3,AO3),"\textbf{","") | AC3: =resultOnlatexABC16Dec24!T8 -> 10023.1 | AD3: =IF(AC3=MIN(E3,Q3,AC3,AO3),"}","") | AE3: & | AF3: =IF(AG3=MIN(I3,U3,AG3,AS3),"\textbf{","") | AG3: =resultOnlatexABC16Dec24!V8 -> 10023.54 | AH3: =IF(AG3=MIN(I3,U3,AG3,AS3),"}","") | AI3: & | AJ3: =resultOnlatexABC16Dec24!X8 -> 4.37 | AK3: & | AL3: =resultOnlatexABC16Dec24!Z8 -> 10020.9 | AM3: & | AN3: =IF(AO3=MIN(E3,Q3,AC3,AO3),"\textbf{","") | AO3: =resultOnlatexABC16Dec24!AB8 -> 10023.1 | AP3: =IF(AO3=MIN(E3,Q3,AC3,AO3),"}","") | AQ3: & | AR3: =IF(AS3=MIN(I3,U3,AG3,AS3),"\textbf{","") | AS3: =resultOnlatexABC16Dec24!AD8 -> 10024.4 | AT3: =IF(AS3=MIN(I3,U3,AG3,AS3),"}","") | AU3: & | AV3: =resultOnlatexABC16Dec24!AF8 -> 11.01 | AW3: & | AX3: =resultOnlatexABC16Dec24!AH8 -> 10020.9 | AY3: \\
B4: 15x4A | C4: & | D4: =IF(E4=MIN(E4,Q4,AC4,AO4),"\textbf{","") -> \textbf{ | E4: =resultOnlatexABC16Dec24!D9 -> 13226.2 | F4: =IF(E4=MIN(E4,Q4,AC4,AO4),"}","") -> } | G4: & | H4: =IF(I4=MIN(I4,U4,AG4,AS4),"\textbf{","") -> \textbf{ | I4: =resultOnlatexABC16Dec24!F9 -> 13226.2 | J4: =IF(I4=MIN(I4,U4,AG4,AS4),"}","") -> } | K4: & | L4: =resultOnlatexABC16Dec24!H9 -> 42.53 | M4: & | N4: =resultOnlatexABC16Dec24!J9 -> 13227.1 | O4: & | P4: =IF(Q4=MIN(E4,Q4,AC4,AO4),"\textbf{","") | Q4: =resultOnlatexABC16Dec24!L9 -> 13751.4 | R4: =IF(Q4=MIN(E4,Q4,AC4,AO4),"}","") | S4: & | T4: =IF(U4=MIN(I4,U4,AG4,AS4),"\textbf{","") | U4: =resultOnlatexABC16Dec24!N9 -> 13751.43 | V4: =IF(U4=MIN(I4,U4,AG4,AS4),"}","") | W4: & | X4: =resultOnlatexABC16Dec24!P9 -> 14.3 | Y4: & | Z4: =resultOnlatexABC16Dec24!R9 -> 13762 | AA4: & | AB4: =IF(AC4=MIN(E4,Q4,AC4,AO4),"\textbf{","") | AC4: =resultOnlatexABC16Dec24!T9 -> 13238.3 | AD4: =IF(AC4=MIN(E4,Q4,AC4,AO4),"}","") | AE4: & | AF4: =IF(AG4=MIN(I4,U4,AG4,AS4),"\textbf{","") | AG4: =resultOnlatexABC16Dec24!V9 -> 13238.3 | AH4: =IF(AG4=MIN(I4,U4,AG4,AS4),"}","") | AI4: & | AJ4: =resultOnlatexABC16Dec24!X9 -> 37.41 | AK4: & | AL4: =resultOnlatexABC16Dec24!Z9 -> 13238.1 | AM4: & | AN4: =IF(AO4=MIN(E4,Q4,AC4,AO4),"\textbf{","") | AO4: =resultOnlatexABC16Dec24!AB9 -> 13238.3 | AP4: =IF(AO4=MIN(E4,Q4,AC4,AO4),"}","") | AQ4: & | AR4: =IF(AS4=MIN(I4,U4,AG4,AS4),"\textbf{","") | AS4: =resultOnlatexABC16Dec24!AD9 -> 13238.3 | AT4: =IF(AS4=MIN(I4,U4,AG4,AS4),"}","") | AU4: & | AV4: =resultOnlatexABC16Dec24!AF9 -> 130.21 | AW4: & | AX4: =resultOnlatexABC16Dec24!AH9 -> 13238.1 | AY4: \\
B5: 20x3A | C5: & | D5: =IF(E5=MIN(E5,Q5,AC5,AO5),"\textbf{","") -> \textbf{ | E5: =resultOnlatexABC16Dec24!D10 -> 17695 | F5: =IF(E5=MIN(E5,Q5,AC5,AO5),"}","") -> } | G5: & | H5: =IF(I5=MIN(I5,U5,AG5,AS5),"\textbf{","") -> \textbf{ | I5: =resultOnlatexABC16Dec24!F10 -> 17695 | J5: =IF(I5=MIN(I5,U5,AG5,AS5),"}","") -> } | K5: & | L5: =resultOnlatexABC16Dec24!H10 -> 128.78 | M5: & | N5: =resultOnlatexABC16Dec24!J10 -> 17695 | O5: & | P5: =IF(Q5=MIN(E5,Q5,AC5,AO5),"\textbf{","") | Q5: =resultOnlatexABC16Dec24!L10 -> 18191.5 | R5: =IF(Q5=MIN(E5,Q5,AC5,AO5),"}","") | S5: & | T5: =IF(U5=MIN(I5,U5,AG5,AS5),"\textbf{","") | U5: =resultOnlatexABC16Dec24!N10 -> 18219.96 | V5: =IF(U5=MIN(I5,U5,AG5,AS5),"}","") | W5: & | X5: =resultOnlatexABC16Dec24!P10 -> 178.79 | Y5: & | Z5: =resultOnlatexABC16Dec24!R10 -> 18191.4 | AA5: & | AB5: =IF(AC5=MIN(E5,Q5,AC5,AO5),"\textbf{","") -> \textbf{ | AC5: =resultOnlatexABC16Dec24!T10 -> 17695 | AD5: =IF(AC5=MIN(E5,Q5,AC5,AO5),"}","") -> } | AE5: & | AF5: =IF(AG5=MIN(I5,U5,AG5,AS5),"\textbf{","") -> \textbf{ | AG5: =resultOnlatexABC16Dec24!V10 -> 17695 | AH5: =IF(AG5=MIN(I5,U5,AG5,AS5),"}","") -> } | AI5: & | AJ5: =resultOnlatexABC16Dec24!X10 -> 88.32 | AK5: & | AL5: =resultOnlatexABC16Dec24!Z10 -> 17695 | AM5: & | AN5: =IF(AO5=MIN(E5,Q5,AC5,AO5),"\textbf{","") -> \textbf{ | AO5: =resultOnlatexABC16Dec24!AB10 -> 17695 | AP5: =IF(AO5=MIN(E5,Q5,AC5,AO5),"}","") -> } | AQ5: & | AR5: =IF(AS5=MIN(I5,U5,AG5,AS5),"\textbf{","") -> \textbf{ | AS5: =resultOnlatexABC16Dec24!AD10 -> 17695 | AT5: =IF(AS5=MIN(I5,U5,AG5,AS5),"}","") -> } | AU5: & | AV5: =resultOnlatexABC16Dec24!AF10 -> 296.08 | AW5: & | AX5: =resultOnlatexABC16Dec24!AH10 -> 17695 | AY5: \\
